Workbook

Sheet CashFlow
A1: Poly-Aluminum Chloride (PAC) Plant - Cash Flow Analysis (Actual)
A3: Key Assumptions & Base Parameters (at 100% Capacity)
A4: Operating Hours (hr/yr) | B4: 7920 | G4: Base Variable OPEX Calculation (Year 1, 100% Util) | M4: Construction Phase Spending
A5: Fixed Capital Investment (FCI) | B5: =CAPEX!P64 -> 13402360 | G5: 1. Raw Materials | M5: Year -2 | N5: =-$B$10*0.3 -> -5984019.8
A6: Working Capital (WC) | B6: =0.15*CAPEX!P64 -> 2010354 | G6: Raw Material | H6: Flow (kg/hr) | I6: Annual (t/opera-yr) | J6: Unit Price ($/t) | K6: Annual Cost (USD) | M6: Year -1 | N6: =-$B$10*0.5 -> -9973366.3
A7: C_GR (Grass-Roots Investment) | B7: =SUM(CAPEX!P64:P67) -> 16484903 | G7: Awaso Bauxite (ROM ore) | H7: 755.99 | I7: =H7*$B$4/1000 -> 5987.4408 | J7: 35 | K7: =I7*J7 -> 209560.43 | M7: Year 0 | N7: =-$B$10*0.2 -> -3989346.5
A8: EPC Fee (10%) | B8: =0.1*B7 -> 1648490.3 | G8: Hydrochloric Acid 32 wt% | H8: 2285 | I8: =H8*$B$4/1000 -> 18097.2 | J8: 180 | K8: =I8*J8 -> 3257496
A9: Contingency (10%) | B9: =0.1*(B8+B7) -> 1813339.3 | G9: Calcium Aluminate (CaAl₂O₄) | H9: 650 | I9: =H9*$B$4/1000 -> 5148 | J9: 310 | K9: =I9*J9 -> 1595880
A10: Total Capital Investment (TCI) | B10: =SUM(B7:B9) -> 19946733 | G10: Carbon Monoxide (WAGP) | H10: 329.25 | I10: =H10*$B$4/1000 -> 2607.66 | J10: 450 | K10: =I10*J10 -> 1173447
A11: Salvage Value | B11: 1244957.3 | G11: Process Water | H11: 833.33 | I11: =H11*$B$4/1000 -> 6599.9736 | J11: 2.73 | K11: =I11*J11 -> 18017.928
A12: Plant Life (Years) | B12: 20 | K12: =SUM(K7:K11) -> 6254401.4
A13: Depreciation Period (Yrs) | B13: 5 | G13: 2. Utilities
A14: Corporate Tax Rate | B14: 0.1875 | G14: Utility | H14: Usage Rate | I14: Annual Usage | J14: Unit Rate ($) | K14: Annual Cost (USD)
A15: Discount Rate (WACC) from AfDB | B15: 0.08 | G15: Electricity (Load) | H15: 150 | I15: =H15*$B$4 -> 1188000 | J15: 0.11 | K15: =I15*J15 + 499.720989114411 -> 131179.72
A16: Inflation (OPEX Blended) | B16: 0.04 | G16: Cooling Water | H16: 40 | I16: =H16*$B$4 -> 316800 | J16: 2.7306262 | K16: =I16*J16 + 249.860494557205 -> 865312.22
A17: Price Escalation | B17: 0.04 | K17: =SUM(K15:K16) -> 996491.95
A18: Plant Capacity (TPA) | B18: 31384.63 | G18: 3. Logistics & Other Variable
A19: Domestic Volume (TPA) | B19: 4000 | G19: Item | K19: Annual Cost (USD)
A20: Domestic Price Base ($/t) | B20: 450 | G20: Logistics & Distribution | K20: 1230000
A21: Export Price Base ($/t) | B21: 480 | G21: Other Variable Costs | K21: 180000
A23: By-Product Revenue Breakdown | G23: Base Fixed OPEX Calculation
A24: By-Product | B24: Flow (kg/hr) | C24: Annual (t/yr) | D24: Unit Price ($/t) | E24: Annual Rev (USD) | G24: Fixed Cost Item | H24: Calculation Basis | K24: Annual Cost (USD)
A25: Silica Residue (Pozzolan) | B25: 260.37 | C25: =B25*$B$4/1000 -> 2062.1304 | D25: 20 | E25: =C25*D25 -> 41242.608 | G25: Labor (Shift + Admin) | H25: Headcount model | K25: =Labour!C30 -> 822000
A26: Magnetite Reject | B26: 57.75 | C26: =B26*$B$4/1000 -> 457.38 | D26: 50 | E26: =C26*D26 -> 22869 | G26: Maintenance | H26: 6% of FCI | K26: =$B$5*0.06 -> 804141.61
A27: Total By-Product Revenue | E27: =SUM(E25:E26) -> 64111.608 | G27: Insurance | H27: 1.5% of FCI | K27: =$B$5*0.015 -> 201035.4
G28: Overheads | H28: 20% of (Labor+Maint) | K28: =(2109515.52050105+K$26)*0.2 -> 582731.43
G29: CSR & Environmental | H29: Fixed | K29: 10000
G30: Property Tax | H30: Fixed | K30: 15000
A34: Year | B34: 1 | C34: 2 | D34: 3 | E34: 4 | F34: 5 | G34: 6 | H34: 7 | I34: 8 | J34: 9 | K34: 10 | L34: 11 | M34: 12 | N34: 13 | O34: 14 | P34: 15 | Q34: 16 | R34: 17 | S34: 18 | T34: 19 | U34: 20
A35: Capacity Utilisation | B35: 0.6 | C35: 0.8 | D35: 1 | E35: 1 | F35: 1 | G35: 1 | H35: 1 | I35: 1 | J35: 1 | K35: 1 | L35: 0.95 | M35: 0.95 | N35: 0.9 | O35: 0.9 | P35: 0.9 | Q35: 0.9 | R35: 0.9 | S35: 0.9 | T35: 0.9 | U35: 0.9
A36: Revenue | B36: =MIN($B$19, $B$18*B35)*$B$20*(1+$B$17)^(B$34-1) + ($B$18*B35-MIN($B$19, $B$18*B35))*$B$21*(1+$B$17)^(B$34-1) + $E$27 -> 8982885 | C36: =MIN($B$19, $B$18*C35)*$B$20*(1+$B$17)^(C$34-1) + ($B$18*C35-MIN($B$19, $B$18*C35))*$B$21*(1+$B$17)^(C$34-1) + $E$27 -> 12473077 | D36: =MIN($B$19, $B$18*D35)*$B$20*(1+$B$17)^(D$34-1) + ($B$18*D35-MIN($B$19, $B$18*D35))*$B$21*(1+$B$17)^(D$34-1) + $E$27 -> 16228215 | E36: =MIN($B$19, $B$18*E35)*$B$20*(1+$B$17)^(E$34-1) + ($B$18*E35-MIN($B$19, $B$18*E35))*$B$21*(1+$B$17)^(E$34-1) + $E$27 -> 16874779 | F36: =MIN($B$19, $B$18*F35)*$B$20*(1+$B$17)^(F$34-1) + ($B$18*F35-MIN($B$19, $B$18*F35))*$B$21*(1+$B$17)^(F$34-1) + $E$27 -> 17547206 | G36: =MIN($B$19, $B$18*G35)*$B$20*(1+$B$17)^(G$34-1) + ($B$18*G35-MIN($B$19, $B$18*G35))*$B$21*(1+$B$17)^(G$34-1) + $E$27 -> 18246530 | H36: =MIN($B$19, $B$18*H35)*$B$20*(1+$B$17)^(H$34-1) + ($B$18*H35-MIN($B$19, $B$18*H35))*$B$21*(1+$B$17)^(H$34-1) + $E$27 -> 18973827 | I36: =MIN($B$19, $B$18*I35)*$B$20*(1+$B$17)^(I$34-1) + ($B$18*I35-MIN($B$19, $B$18*I35))*$B$21*(1+$B$17)^(I$34-1) + $E$27 -> 19730215 | ... U36: =MIN($B$19, $B$18*U35)*$B$20*(1+$B$17)^(U$34-1) + ($B$18*U35-MIN($B$19, $B$18*U35))*$B$21*(1+$B$17)^(U$34-1) + $E$27 -> 28376288
A37: RM: Awaso Bauxite (ROM ore) | B37: =$K$7*B35*(1+$B$16)^(B$34-1) -> 125736.26 | C37: =$K$7*C35*(1+$B$16)^(C$34-1) -> 174354.28 | D37: =$K$7*D35*(1+$B$16)^(D$34-1) -> 226660.56 | E37: =$K$7*E35*(1+$B$16)^(E$34-1) -> 235726.98 | F37: =$K$7*F35*(1+$B$16)^(F$34-1) -> 245156.06 | G37: =$K$7*G35*(1+$B$16)^(G$34-1) -> 254962.3 | H37: =$K$7*H35*(1+$B$16)^(H$34-1) -> 265160.8 | I37: =$K$7*I35*(1+$B$16)^(I$34-1) -> 275767.23 | ... U37: =$K$7*U35*(1+$B$16)^(U$34-1) -> 397360.99
A38: RM: Hydrochloric Acid 32 wt% | B38: =$K$8*B35*(1+$B$16)^(B$34-1) -> 1954497.6 | C38: =$K$8*C35*(1+$B$16)^(C$34-1) -> 2710236.7 | D38: =$K$8*D35*(1+$B$16)^(D$34-1) -> 3523307.7 | E38: =$K$8*E35*(1+$B$16)^(E$34-1) -> 3664240 | F38: =$K$8*F35*(1+$B$16)^(F$34-1) -> 3810809.6 | G38: =$K$8*G35*(1+$B$16)^(G$34-1) -> 3963242 | H38: =$K$8*H35*(1+$B$16)^(H$34-1) -> 4121771.6 | I38: =$K$8*I35*(1+$B$16)^(I$34-1) -> 4286642.5 | ... U38: =$K$8*U35*(1+$B$16)^(U$34-1) -> 6176747.5
A39: RM: Calcium Aluminate (CaAl₂O₄) | B39: =$K$9*B35*(1+$B$16)^(B$34-1) -> 957528 | C39: =$K$9*C35*(1+$B$16)^(C$34-1) -> 1327772.2 | D39: =$K$9*D35*(1+$B$16)^(D$34-1) -> 1726103.8 | E39: =$K$9*E35*(1+$B$16)^(E$34-1) -> 1795148 | F39: =$K$9*F35*(1+$B$16)^(F$34-1) -> 1866953.9 | G39: =$K$9*G35*(1+$B$16)^(G$34-1) -> 1941632 | H39: =$K$9*H35*(1+$B$16)^(H$34-1) -> 2019297.3 | I39: =$K$9*I35*(1+$B$16)^(I$34-1) -> 2100069.2 | ... U39: =$K$9*U35*(1+$B$16)^(U$34-1) -> 3026050.6
A40: RM: Carbon Monoxide (industrial grade) | B40: =$K$10*B35*(1+$B$16)^(B$34-1) -> 704068.2 | C40: =$K$10*C35*(1+$B$16)^(C$34-1) -> 976307.9 | D40: =$K$10*D35*(1+$B$16)^(D$34-1) -> 1269200.3 | E40: =$K$10*E35*(1+$B$16)^(E$34-1) -> 1319968.3 | F40: =$K$10*F35*(1+$B$16)^(F$34-1) -> 1372767 | G40: =$K$10*G35*(1+$B$16)^(G$34-1) -> 1427677.7 | H40: =$K$10*H35*(1+$B$16)^(H$34-1) -> 1484784.8 | I40: =$K$10*I35*(1+$B$16)^(I$34-1) -> 1544176.2 | ... U40: =$K$10*U35*(1+$B$16)^(U$34-1) -> 2225048.3
A41: RM: Process Water | B41: =$K$11*B35*(1+$B$16)^(B$34-1) -> 10810.757 | C41: =$K$11*C35*(1+$B$16)^(C$34-1) -> 14990.916 | D41: =$K$11*D35*(1+$B$16)^(D$34-1) -> 19488.191 | E41: =$K$11*E35*(1+$B$16)^(E$34-1) -> 20267.718 | F41: =$K$11*F35*(1+$B$16)^(F$34-1) -> 21078.427 | G41: =$K$11*G35*(1+$B$16)^(G$34-1) -> 21921.564 | H41: =$K$11*H35*(1+$B$16)^(H$34-1) -> 22798.427 | I41: =$K$11*I35*(1+$B$16)^(I$34-1) -> 23710.364 | ... U41: =$K$11*U35*(1+$B$16)^(U$34-1) -> 34164.951
A42: Util: Electricity | B42: =$K$15*B35*(1+$B$16)^(B$34-1) -> 78707.833 | C42: =$K$15*C35*(1+$B$16)^(C$34-1) -> 109141.53 | D42: =$K$15*D35*(1+$B$16)^(D$34-1) -> 141883.99 | E42: =$K$15*E35*(1+$B$16)^(E$34-1) -> 147559.35 | F42: =$K$15*F35*(1+$B$16)^(F$34-1) -> 153461.72 | G42: =$K$15*G35*(1+$B$16)^(G$34-1) -> 159600.19 | H42: =$K$15*H35*(1+$B$16)^(H$34-1) -> 165984.2 | I42: =$K$15*I35*(1+$B$16)^(I$34-1) -> 172623.56 | ... U42: =$K$15*U35*(1+$B$16)^(U$34-1) -> 248738.3
A43: Util: Cooling Water | B43: =$K$16*B35*(1+$B$16)^(B$34-1) -> 519187.33 | C43: =$K$16*C35*(1+$B$16)^(C$34-1) -> 719939.77 | D43: =$K$16*D35*(1+$B$16)^(D$34-1) -> 935921.7 | E43: =$K$16*E35*(1+$B$16)^(E$34-1) -> 973358.57 | F43: =$K$16*F35*(1+$B$16)^(F$34-1) -> 1012292.9 | G43: =$K$16*G35*(1+$B$16)^(G$34-1) -> 1052784.6 | H43: =$K$16*H35*(1+$B$16)^(H$34-1) -> 1094896 | I43: =$K$16*I35*(1+$B$16)^(I$34-1) -> 1138691.9 | ... U43: =$K$16*U35*(1+$B$16)^(U$34-1) -> 1640774.1
A44: Logistics & Distribution | B44: =$K$20*B35*(1+$B$16)^(B$34-1) -> 738000 | C44: =$K$20*C35*(1+$B$16)^(C$34-1) -> 1023360 | D44: =$K$20*D35*(1+$B$16)^(D$34-1) -> 1330368 | E44: =$K$20*E35*(1+$B$16)^(E$34-1) -> 1383582.7 | F44: =$K$20*F35*(1+$B$16)^(F$34-1) -> 1438926 | G44: =$K$20*G35*(1+$B$16)^(G$34-1) -> 1496483.1 | H44: =$K$20*H35*(1+$B$16)^(H$34-1) -> 1556342.4 | I44: =$K$20*I35*(1+$B$16)^(I$34-1) -> 1618596.1 | ... U44: =$K$20*U35*(1+$B$16)^(U$34-1) -> 2332282
A45: Other Variable Costs | B45: =$K$21*B35*(1+$B$16)^(B$34-1) -> 108000 | C45: =$K$21*C35*(1+$B$16)^(C$34-1) -> 149760 | D45: =$K$21*D35*(1+$B$16)^(D$34-1) -> 194688 | E45: =$K$21*E35*(1+$B$16)^(E$34-1) -> 202475.52 | F45: =$K$21*F35*(1+$B$16)^(F$34-1) -> 210574.54 | G45: =$K$21*G35*(1+$B$16)^(G$34-1) -> 218997.52 | H45: =$K$21*H35*(1+$B$16)^(H$34-1) -> 227757.42 | I45: =$K$21*I35*(1+$B$16)^(I$34-1) -> 236867.72 | ... U45: =$K$21*U35*(1+$B$16)^(U$34-1) -> 341309.57
...

Sheet Labour
A1: PAC Plant Labour Force & Economics Breakdown
A3: 1. Shift Labour Costs
A4: Role | B4: Premium Annual Salary (USD) | C4: Staff per Shift | D4: Total Crews | E4: Total Headcount | F4: Total Annual Cost (USD)
A5: Shift Supervisor | B5: 12000 | C5: 1 | D5: 4 | E5: =C5*D5 -> 4 | F5: =B5*E5 -> 48000
A6: DCS / Panel Operator | B6: 7500 | C6: 2 | D6: 4 | E6: =C6*D6 -> 8 | F6: =B6*E6 -> 60000
A7: Field Operator | B7: 6000 | C7: 8 | D7: 4 | E7: =C7*D7 -> 32 | F7: =B7*E7 -> 192000
A8: Mechanical Fitter | B8: 7500 | C8: 2 | D8: 4 | E8: =C8*D8 -> 8 | F8: =B8*E8 -> 60000
A9: Elec / Instrument Tech | B9: 7500 | C9: 2 | D9: 4 | E9: =C9*D9 -> 8 | F9: =B9*E9 -> 60000
A10: Lab Analyst | B10: 6500 | C10: 2 | D10: 4 | E10: =C10*D10 -> 8 | F10: =B10*E10 -> 52000
A11: HSE Officer | B11: 7000 | C11: 1 | D11: 4 | E11: =C11*D11 -> 4 | F11: =B11*E11 -> 28000
A12: Weighbridge Operator | B12: 5000 | C12: 1 | D12: 4 | E12: =C12*D12 -> 4 | F12: =B12*E12 -> 20000
A13: Security Guard | B13: 3000 | C13: 3 | D13: 4 | E13: =C13*D13 -> 12 | F13: =B13*E13 -> 36000
A14: Subtotal (Shift) | C14: =SUM(C5:C13) -> 22 | E14: =SUM(E5:E13) -> 88 | F14: =SUM(F5:F13) -> 556000
A16: 2. Day & Administrative Labour Costs
A17: Role | B17: Premium Annual Salary (USD) | C17: Total Headcount | D17: Total Annual Cost (USD)
A18: Plant Manager | B18: 28000 | C18: 1 | D18: =B18*C18 -> 28000
A19: Department Managers | B19: 20000 | C19: 5 | D19: =B19*C19 -> 100000
A20: Engineers | B20: 15000 | C20: 4 | D20: =B20*C20 -> 60000
A21: Admin/Procurement/HR | B21: 8000 | C21: 4 | D21: =B21*C21 -> 32000
A22: Day Maintenance Crew | B22: 7000 | C22: 4 | D22: =B22*C22 -> 28000
A23: General Laborers | B23: 3000 | C23: 6 | D23: =B23*C23 -> 18000
A24: Subtotal (Admin) | C24: =SUM(C18:C23) -> 24 | D24: =SUM(D18:D23) -> 266000
A26: 3. Total Annual OPEX Contribution
A27: Category | B27: Headcount | C27: Annual Cost (USD)
A28: Total Shift Labour | B28: =E14 -> 88 | C28: =F14 -> 556000
A29: Total Admin Labour | B29: =C24 -> 24 | C29: =D24 -> 266000
A30: TOTAL LABOUR COST | B30: =SUM(B28:B29) -> 112 | C30: =SUM(C28:C29) -> 822000

Sheet CAPEX
A1: Equipment Tag | B1: Description | C1: Size (A) | D1: Unit | E1: K1 | F1: K2 | G1: K3 | H1: Base Cost C°p (USD) | I1: B1 | J1: B2 | K1: Fm | L1: Fp | M1: F_BM | N1: C_BM_2001 (USD) | O1: CEPCI Ratio (2026/2001) | P1: C_BM_2026 (USD) | Q1: Notes
A2: CRN-101 (Done) | B2: Gantry Crane, grab bucket | C2: 5 | D2: t SWL | H2: 45000 | I2: 0 | J2: 1 | K2: 1.5 | L2: 1 | M2: =IF(ISBLANK(I2), 1.5, I2+J2*K2*L2) -> 1.5 | N2: =H2*M2 -> 67500 | O2: 1.7088161 | P2: =N2*O2 -> 115345.09 | Q2: Overhead Crane, Imported, CS/galvanised | R2: =SUM(P2:P6) -> 257074.13
A3: FD-101 (Done) | B3: Vibrating feeder + hopper | C3: 0.76 | D3: t/hr | E3: 3.2086 | F3: 0.3236 | G3: 0.0645 | H3: =IF(ISBLANK(E3), 18000, 10^(E3+F3*LOG10(C3)+G3*(LOG10(C3))^2)) -> 1482.339 | I3: 0 | J3: 1 | K3: 1.5 | L3: 1 | M3: =IF(ISBLANK(I3), 1.5, I3+J3*K3*L3) -> 1.5 | N3: =H3*M3 -> 2223.5085 | O3: 1.7088161 | P3: =N3*O3 -> 3799.5671 | Q3: Belt/Feeder (Carbon steel)
A4: CR-101 (Done) | B4: Jaw Crusher | C4: 1.5 | D4: kW | E4: 3.5 | F4: 0.7 | G4: 0 | H4: =IF(ISBLANK(E4), 18000, 10^(E4+F4*LOG10(C4)+G4*(LOG10(C4))^2)) -> 4200.1411 | I4: 1.25 | J4: 0.45 | K4: 2.1 | L4: 1 | M4: =IF(ISBLANK(I4), 1.5, I4+J4*K4*L4) -> 2.195 | N4: =H4*M4 -> 9219.3097 | O4: 1.7088161 | P4: =N4*O4 -> 15754.105 | Q4: Hadfield manganese steel
A5: CV-101 (Done)** | B5: Belt Conveyor (enclosed) | C5: 15 | D5: m, 0.76 t/hr | E5: 4.0637 | F5: -0.7416 | G5: 0.155 | H5: =IF(ISBLANK(E5), 18000, 10^(E5+F5*LOG10(C5)+G5*(LOG10(C5))^2)) -> 2546.2748 | I5: 0 | J5: 1 | K5: 1.5 | L5: 1 | M5: =IF(ISBLANK(I5), 1.5, I5+J5*K5*L5) -> 1.5 | N5: =H5*M5 -> 3819.4122 | O5: 1.7088161 | P5: =N5*O5 -> 6526.6732 | Q5: Rubber belt, CS frame
A6: BN-101 (Done} | B6: Day Bin (crushed ore) | C6: 17.5 | D6: m³ | E6: 3.4974 | F6: 0.4485 | G6: 0.1074 | H6: =IF(ISBLANK(E6), 18000, 10^(E6+F6*LOG10(C6)+G6*(LOG10(C6))^2)) -> 16628.42 | I6: 2.25 | J6: 1.82 | K6: 1 | L6: 1 | M6: =IF(ISBLANK(I6), 1.5, I6+J6*K6*L6) -> 4.07 | N6: =H6*M6 -> 67677.67 | O6: 1.7088161 | P6: =N6*O6 -> 115648.69 | Q6: Carbon steel
A7: FD-201 (Done) | B7: Screw Feeder | C7: 0.5 | D7: m² | E7: 3.6062 | F7: 0.2659 | G7: 0.1982 | H7: =IF(ISBLANK(E7), 18000, 10^(E7+F7*LOG10(C7)+G7*(LOG10(C7))^2)) -> 3500.3931 | I7: 0 | J7: 1 | K7: 1.5 | L7: 1 | M7: =IF(ISBLANK(I7), 1.5, I7+J7*K7*L7) -> 1.5 | N7: =H7*M7 -> 5250.5897 | O7: 1.7088161 | P7: 3625 | Q7: CS, compact | R7: https://abchansenafrica.co.za/wp/product/trough-augers/
A8: RK-201 (Done) | B8: Counter-current Rotary Kiln | C8: 31.42 | D8: m² | E8: 3.5645 | F8: 1.1118 | G8: -0.077 | H8: =IF(ISBLANK(E8), 18000, 10^(E8+F8*LOG10(C8)+G8*(LOG10(C8))^2)) -> 113890.79 | I8: 1.49 | J8: 1.52 | K8: 3.7 | L8: 1 | M8: =IF(ISBLANK(I8), 1.5, I8+J8*K8*L8) -> 7.114 | N8: =H8*M8 -> 810219.08 | O8: 1.7088161 | P8: =N8*O8 -> 1384515.4 | Q8: Incoloy alloy shell | R8: =SUM(P7:P12) -> 1835589.6
A9: BR-201 (Done) | B9: Kiln Burner | C9: 300 | D9: kW thermal | E9: 3.0681 | F9: 0.65 | G9: 0.0287 | H9: =IF(ISBLANK(E9), 18000, 10^(E9+F9*LOG10(C9)+G9*(LOG10(C9))^2)) -> 71504.889 | I9: 1.49 | J9: 1.52 | K9: 1 | L9: 1 | M9: =IF(ISBLANK(I9), 1.5, I9+J9*K9*L9) -> 3.01 | N9: 2700 | O9: 1.7088161 | P9: =N9*O9 -> 4613.8035 | Q9: Industrial burner | R9: https://dir.indiamart.com/impcat/industrial-gas-burner.html
A10: E-201 | B10: Gas-Gas Air Preheater | C10: 0.33 | D10: m² | E10: 4.3247 | F10: -0.303 | G10: 0.1634 | H10: =IF(ISBLANK(E10), 18000, 10^(E10+F10*LOG10(C10)+G10*(LOG10(C10))^2)) -> 32245.648 | I10: 1.63 | J10: 1.66 | K10: 2.75 | L10: 1 | M10: =IF(ISBLANK(I10), 1.5, I10+J10*K10*L10) -> 6.195 | N10: =H10*M10 -> 199761.79 | O10: 1.7088161 | P10: =N10*O10 -> 341356.16 | Q10: High-temp SS
A11: CL-201 | B11: Rotary Tube Cooler | C11: 3.34 | D11: m² | E11: 4.3247 | F11: -0.303 | G11: 0.1634 | H11: =IF(ISBLANK(E11), 18000, 10^(E11+F11*LOG10(C11)+G11*(LOG10(C11))^2)) -> 16249.019 | I11: 1.63 | J11: 1.66 | K11: 1 | L11: 1 | M11: =IF(ISBLANK(I11), 1.5, I11+J11*K11*L11) -> 3.29 | N11: =H11*M11 -> 53459.271 | O11: 1.7088161 | P11: =N11*O11 -> 91352.064 | Q11: Incoloy 800H tubes
A12: CV-201 | B12: Drag Conveyor | C12: 10 | D12: m, 0.76 t/hr | E12: 3.2086 | F12: 0.3236 | G12: 0.0645 | H12: =IF(ISBLANK(E12), 18000, 10^(E12+F12*LOG10(C12)+G12*(LOG10(C12))^2)) -> 3950.936 | I12: 0 | J12: 1 | K12: 1.5 | L12: 1 | M12: =IF(ISBLANK(I12), 1.5, I12+J12*K12*L12) -> 1.5 | N12: =H12*M12 -> 5926.4041 | O12: 1.7088161 | P12: =N12*O12 -> 10127.135 | Q12: CS with abrasion plates
A13: E-301 | B13: Waste Heat Boiler | C13: 300 | D13: kW | E13: 4.3247 | F13: -0.303 | G13: 0.1634 | H13: =IF(ISBLANK(E13), 18000, 10^(E13+F13*LOG10(C13)+G13*(LOG10(C13))^2)) -> 37737.737 | I13: 1.63 | J13: 1.66 | K13: 1 | L13: 1 | M13: =IF(ISBLANK(I13), 1.5, I13+J13*K13*L13) -> 3.29 | N13: =H13*M13 -> 124157.16 | O13: 1.7088161 | P13: =N13*O13 -> 212161.75 | Q13: CS shell | R13: =SUM(P13:P19) -> 1691249.4
A14: CY-301 | B14: Cyclone Separator | C14: 0.18 | D14: m dia | E14: 4.1378 | F14: 0.1678 | G14: 0.0988 | H14: =IF(ISBLANK(E14), 18000, 10^(E14+F14*LOG10(C14)+G14*(LOG10(C14))^2)) -> 11685.064 | I14: 0 | J14: 1 | K14: 1.5 | L14: 1 | M14: =IF(ISBLANK(I14), 1.5, I14+J14*K14*L14) -> 1.5 | N14: =H14*M14 -> 17527.596 | O14: 1.7088161 | P14: =N14*O14 -> 29951.438 | Q14: Standard CS
A15: CL-301 | B15: Evaporative Cooler | C15: 200 | D15: kW duty | E15: 4.3247 | F15: -0.303 | G15: 0.1634 | H15: =IF(ISBLANK(E15), 18000, 10^(E15+F15*LOG10(C15)+G15*(LOG10(C15))^2)) -> 31091.972 | I15: 1.63 | J15: 1.66 | K15: 1 | L15: 1 | M15: =IF(ISBLANK(I15), 1.5, I15+J15*K15*L15) -> 3.29 | N15: =H15*M15 -> 102292.59 | O15: 1.7088161 | P15: =N15*O15 -> 174799.22 | Q15: CS shell
A16: BH-301 | B16: Pulse-Jet Baghouse | C16: 2 | D16: cells x 6 bags | E16: 4.2255 | F16: 0.505 | G16: -0.045 | H16: =IF(ISBLANK(E16), 18000, 10^(E16+F16*LOG10(C16)+G16*(LOG10(C16))^2)) -> 23628.834 | I16: 0 | J16: 1 | K16: 2 | L16: 1 | M16: =IF(ISBLANK(I16), 1.5, I16+J16*K16*L16) -> 2 | N16: =H16*M16 -> 47257.668 | O16: 1.7088161 | P16: =N16*O16 -> 80754.665 | Q16: Ceramic candles
A17: FN-301 | B17: Induced Draft Fan | C17: 15 | D17: kW | E17: 2.4697 | F17: 1.4398 | G17: -0.1776 | H17: =IF(ISBLANK(E17), 18000, 10^(E17+F17*LOG10(C17)+G17*(LOG10(C17))^2)) -> 8267.6396 | I17: 0 | J17: 1 | K17: 1.5 | L17: 1 | M17: =IF(ISBLANK(I17), 1.5, I17+J17*K17*L17) -> 1.5 | N17: =H17*M17 -> 12401.459 | O17: 1.7088161 | P17: =N17*O17 -> 21191.814 | Q17: CS standard
A18: SC-301 | B18: Emergency Wet Scrubber | C18: 300 | D18: mm dia | E18: 3.4974 | F18: 0.4485 | G18: 0.1074 | H18: =IF(ISBLANK(E18), 18000, 10^(E18+F18*LOG10(C18)+G18*(LOG10(C18))^2)) -> 185101.19 | I18: 2.25 | J18: 1.82 | K18: 2 | L18: 1 | M18: =IF(ISBLANK(I18), 1.5, I18+J18*K18*L18) -> 5.89 | N18: =H18*M18 -> 1090246 | O18: 1.7088161 | P18: 1000000 | Q18: FRP shell | R18: Alterated
A19: ST-301 | B19: Atmospheric Stack | C19: 30 | D19: m | E19: 3.4974 | F19: 0.4485 | G19: 0.1074 | H19: =IF(ISBLANK(E19), 18000, 10^(E19+F19*LOG10(C19)+G19*(LOG10(C19))^2)) -> 24786.977 | I19: 2.25 | J19: 1.82 | K19: 1 | L19: 1 | M19: =IF(ISBLANK(I19), 1.5, I19+J19*K19*L19) -> 4.07 | N19: =H19*M19 -> 100883 | O19: 1.7088161 | P19: =N19*O19 -> 172390.49 | Q19: CS
A20: MS-401 | B20: HIMS Drum Separator | C20: 0.6 | D20: t/hr feed | E20: 4.5126 | F20: 0.2989 | G20: 0.0163 | H20: =IF(ISBLANK(E20), 18000, 10^(E20+F20*LOG10(C20)+G20*(LOG10(C20))^2)) -> 27995.72 | I20: 0 | J20: 1 | K20: 2.5 | L20: 1 | M20: =IF(ISBLANK(I20), 1.5, I20+J20*K20*L20) -> 2.5 | N20: =H20*M20 -> 69989.3 | O20: 1.7088161 | P20: =N20*O20 -> 119598.84 | Q20: 316L SS | R20: =SUM(P20:P23) -> 190628.01
A21: CV-401 | B21: Non-mag belt conveyor | C21: 10 | D21: m | E21: 3.2086 | F21: 0.3236 | G21: 0.0645 | H21: =IF(ISBLANK(E21), 18000, 10^(E21+F21*LOG10(C21)+G21*(LOG10(C21))^2)) -> 3950.936 | I21: 0 | J21: 1 | K21: 1.5 | L21: 1 | M21: =IF(ISBLANK(I21), 1.5, I21+J21*K21*L21) -> 1.5 | N21: =H21*M21 -> 5926.4041 | O21: 1.7088161 | P21: =N21*O21 -> 10127.135 | Q21: CS frame
A22: CV-402 | B22: Mag belt conveyor | C22: 10 | D22: m | E22: 3.2086 | F22: 0.3236 | G22: 0.0645 | H22: =IF(ISBLANK(E22), 18000, 10^(E22+F22*LOG10(C22)+G22*(LOG10(C22))^2)) -> 3950.936 | I22: 0 | J22: 1 | K22: 1.5 | L22: 1 | M22: =IF(ISBLANK(I22), 1.5, I22+J22*K22*L22) -> 1.5 | N22: =H22*M22 -> 5926.4041 | O22: 1.7088161 | P22: =N22*O22 -> 10127.135 | Q22: CS frame
A23: BN-401 | B23: Magnetite Storage Silo | C23: 5 | D23: m³ | E23: 3.4974 | F23: 0.4485 | G23: 0.1074 | H23: =IF(ISBLANK(E23), 18000, 10^(E23+F23*LOG10(C23)+G23*(LOG10(C23))^2)) -> 7300.6124 | I23: 2.25 | J23: 1.82 | K23: 1 | L23: 1 | M23: =IF(ISBLANK(I23), 1.5, I23+J23*K23*L23) -> 4.07 | N23: =H23*M23 -> 29713.492 | O23: 1.7088161 | P23: =N23*O23 -> 50774.895 | Q23: CS
A24: BN-501 | B24: Alumina Feed Bin | C24: 3 | D24: m³ | E24: 3.4974 | F24: 0.4485 | G24: 0.1074 | H24: =IF(ISBLANK(E24), 18000, 10^(E24+F24*LOG10(C24)+G24*(LOG10(C24))^2)) -> 5442.9948 | I24: 2.25 | J24: 1.82 | K24: 1 | L24: 1 | M24: =IF(ISBLANK(I24), 1.5, I24+J24*K24*L24) -> 4.07 | N24: =H24*M24 -> 22152.989 | O24: 1.7088161 | P24: =N24*O24 -> 37855.385 | Q24: CS | R24: =SUM(P24:P30) -> 368854.65
A25: FD-501 | B25: Weight Belt Feeder | C25: 0.69 | D25: t/hr | E25: 3.2086 | F25: 0.3236 | G25: 0.0645 | H25: =IF(ISBLANK(E25), 18000, 10^(E25+F25*LOG10(C25)+G25*(LOG10(C25))^2)) -> 1439.2181 | I25: 0 | J25: 1 | K25: 1.5 | L25: 1 | M25: =IF(ISBLANK(I25), 1.5, I25+J25*K25*L25) -> 1.5 | N25: =H25*M25 -> 2158.8271 | O25: 1.7088161 | P25: =N25*O25 -> 3689.0386 | Q25: CS
A26: TK-501 | B26: Slurry Make-up Tank | C26: 2.5 | D26: m³ | E26: 3.4974 | F26: 0.4485 | G26: 0.1074 | H26: =IF(ISBLANK(E26), 18000, 10^(E26+F26*LOG10(C26)+G26*(LOG10(C26))^2)) -> 4930.4159 | I26: 2.25 | J26: 1.82 | K26: 1 | L26: 1 | M26: =IF(ISBLANK(I26), 1.5, I26+J26*K26*L26) -> 4.07 | N26: =H26*M26 -> 20066.793 | O26: 1.7088161 | P26: =N26*O26 -> 34290.459 | Q26: FRP vinyl ester
A27: P-501 (Done) | B27: Ball Mill Feed Pump | C27: 1.74 | D27: m³/hr | E27: 3.3892 | F27: 0.0536 | G27: 0.1538 | H27: =IF(ISBLANK(E27), 18000, 10^(E27+F27*LOG10(C27)+G27*(LOG10(C27))^2)) -> 2576.2791 | I27: 0 | J27: 1 | K27: 1.6 | L27: 1 | M27: =IF(ISBLANK(I27), 1.5, I27+J27*K27*L27) -> 1.6 | N27: =H27*M27 -> 4122.0466 | O27: 1.7088161 | P27: =N27*O27 -> 7043.8197 | Q27: Rubber-lined
A28: ML-501 (Done) | B28: Ball Mill | C28: 30 | D28: kW motor | H28: =IF(ISBLANK(E28), 90000, 10^(E28+F28*LOG10(C28)+G28*(LOG10(C28))^2)) -> 90000 | M28: =IF(ISBLANK(I28), 1.5, I28+J28*K28*L28) -> 1.5 | N28: =H28*M28 -> 135000 | O28: 1.7088161 | P28: =N28*O28 -> 230690.18 | Q28: High Chomium Cast Iron
A29: P-502 (Done) | B29: Mill Discharge Pump | C29: 1.74 | D29: m³/hr | E29: 3.3892 | F29: 0.0536 | G29: 0.1538 | H29: =IF(ISBLANK(E29), 18000, 10^(E29+F29*LOG10(C29)+G29*(LOG10(C29))^2)) -> 2576.2791 | I29: 0 | J29: 1 | K29: 1.6 | L29: 1 | M29: =IF(ISBLANK(I29), 1.5, I29+J29*K29*L29) -> 1.6 | N29: =H29*M29 -> 4122.0466 | O29: 1.7088161 | P29: =N29*O29 -> 7043.8197 | Q29: Rubber-lined
A30: HC-501 | B30: Hydrocyclone Cluster | C30: 4 | D30: x 0.30 m dia | E30: 4.1378 | F30: 0.1678 | G30: 0.0988 | H30: =IF(ISBLANK(E30), 18000, 10^(E30+F30*LOG10(C30)+G30*(LOG10(C30))^2)) -> 18820.81 | I30: 0 | J30: 1 | K30: 1.5 | L30: 1 | M30: =IF(ISBLANK(I30), 1.5, I30+J30*K30*L30) -> 1.5 | N30: =H30*M30 -> 28231.216 | O30: 1.7088161 | P30: =N30*O30 -> 48241.956 | Q30: Polyurethane lined
A31: TK-601 | B31: HCl Storage Tank | C31: 310 | D31: m³ | E31: 3.4974 | F31: 0.4485 | G31: 0.1074 | H31: =IF(ISBLANK(E31), 18000, 10^(E31+F31*LOG10(C31)+G31*(LOG10(C31))^2)) -> 191159.09 | I31: 2.25 | J31: 1.82 | K31: 1 | L31: 1 | M31: =IF(ISBLANK(I31), 1.5, I31+J31*K31*L31) -> 4.07 | N31: =H31*M31 -> 778017.51 | O31: 1.7088161 | P31: =N31*O31 -> 1329488.9 | Q31: FRP + PE liner | R31: =SUM(P31:P39) -> 3986657.9
A32: P-601 (Done) | B32: HCl Dosing Pump | C32: 1.2 | D32: m³/hr | E32: 3.3892 | F32: 0.0536 | G32: 0.1538 | H32: =IF(ISBLANK(E32), 18000, 10^(E32+F32*LOG10(C32)+G32*(LOG10(C32))^2)) -> 2479.7528 | I32: 1.89 | J32: 1.35 | K32: 2 | L32: 1 | M32: =IF(ISBLANK(I32), 1.5, I32+J32*K32*L32) -> 4.59 | N32: =H32*M32 -> 11382.065 | O32: 1.7088161 | P32: =N32*O32 -> 19449.857 | Q32: PTFE mag-drive
A33: R-601 (Done) | B33: Leach Reactor Train (Done) | C33: 12 | D33: m³ | H33: =IF(ISBLANK(E33), 164000, 10^(E33+F33*LOG10(C33)+G33*(LOG10(C33))^2)) -> 164000 | I33: 2.25 | J33: 1.82 | K33: 1.6 | L33: 1 | M33: =IF(ISBLANK(I33), 1.5, I33+J33*K33*L33) -> 5.162 | N33: =H33*M33 -> 846568 | O33: 1.7088161 | P33: =N33*O33 -> 1446629 | Q33: Borosilicate Enamel lining, Carbon Steel exterior
A34: SC-601 | B34: HCl Scrubber | C34: 300 | D34: mm dia | E34: 3.4974 | F34: 0.4485 | G34: 0.1074 | H34: =IF(ISBLANK(E34), 18000, 10^(E34+F34*LOG10(C34)+G34*(LOG10(C34))^2)) -> 185101.19 | I34: 2.25 | J34: 1.82 | K34: 2 | L34: 1 | M34: =IF(ISBLANK(I34), 1.5, I34+J34*K34*L34) -> 5.89 | N34: =H34*M34 -> 1090246 | O34: 1.7088161 | P34: 800000 | Q34: CPVC shell | R34: Alterated
A35: P-602 (Done) | B35: Leach Slurry Pump | C35: 2.65 | D35: m³/hr | E35: 3.3892 | F35: 0.0536 | G35: 0.1538 | H35: =IF(ISBLANK(E35), 18000, 10^(E35+F35*LOG10(C35)+G35*(LOG10(C35))^2)) -> 2750.6622 | I35: 1.89 | J35: 1.35 | K35: 2 | L35: 1 | M35: =IF(ISBLANK(I35), 1.5, I35+J35*K35*L35) -> 4.59 | N35: =H35*M35 -> 12625.54 | O35: 1.7088161 | P35: =N35*O35 -> 21574.725 | Q35: Rubber-lined
A36: FP-601 (Done) | B36: High-Pressure Filter Press | C36: 22 | D36: m² | E36: 4.03 | F36: 0.4851 | G36: 0.0384 | H36: =IF(ISBLANK(E36), 18000, 10^(E36+F36*LOG10(C36)+G36*(LOG10(C36))^2)) -> 56287.224 | I36: 0 | J36: 1 | K36: 2.5 | L36: 1 | M36: =IF(ISBLANK(I36), 1.5, I36+J36*K36*L36) -> 2.5 | N36: =H36*M36 -> 140718.06 | O36: 1.7088161 | P36: =N36*O36 -> 240461.29 | Q36: PP filter plates
A37: CV-601 | B37: Filter Cake Conveyor | C37: 8 | D37: m | E37: 3.2086 | F37: 0.3236 | G37: 0.0645 | H37: =IF(ISBLANK(E37), 18000, 10^(E37+F37*LOG10(C37)+G37*(LOG10(C37))^2)) -> 3576.3852 | I37: 0 | J37: 1 | K37: 1.5 | L37: 1 | M37: =IF(ISBLANK(I37), 1.5, I37+J37*K37*L37) -> 1.5 | N37: =H37*M37 -> 5364.5777 | O37: 1.7088161 | P37: =N37*O37 -> 9167.0769 | Q37: CS
A38: BN-601 | B38: Residue Silo | C38: 10 | D38: m³ | E38: 3.4974 | F38: 0.4485 | G38: 0.1074 | H38: =IF(ISBLANK(E38), 18000, 10^(E38+F38*LOG10(C38)+G38*(LOG10(C38))^2)) -> 11305.766 | I38: 2.25 | J38: 1.82 | K38: 1 | L38: 1 | M38: =IF(ISBLANK(I38), 1.5, I38+J38*K38*L38) -> 4.07 | N38: =H38*M38 -> 46014.468 | O38: 1.7088161 | P38: =N38*O38 -> 78630.265 | Q38: CS
A39: TK-602 | B39: PLP Holding Tank | C39: 3.5 | D39: m³ | E39: 3.4974 | F39: 0.4485 | G39: 0.1074 | H39: =IF(ISBLANK(E39), 18000, 10^(E39+F39*LOG10(C39)+G39*(LOG10(C39))^2)) -> 5932.0663 | I39: 2.25 | J39: 1.82 | K39: 1 | L39: 1 | M39: =IF(ISBLANK(I39), 1.5, I39+J39*K39*L39) -> 4.07 | N39: =H39*M39 -> 24143.51 | O39: 1.7088161 | P39: =N39*O39 -> 41256.819 | Q39: FRP vinyl ester
A40: TK-701 | B40: CaAl₂O₄ Make-up Tank | C40: 0.6 | D40: m³ | E40: 3.4974 | F40: 0.4485 | G40: 0.1074 | H40: =IF(ISBLANK(E40), 18000, 10^(E40+F40*LOG10(C40)+G40*(LOG10(C40))^2)) -> 2530.3857 | I40: 2.25 | J40: 1.82 | K40: 1 | L40: 1 | M40: =IF(ISBLANK(I40), 1.5, I40+J40*K40*L40) -> 4.07 | N40: =H40*M40 -> 10298.67 | O40: 1.7088161 | P40: =N40*O40 -> 17598.533 | Q40: FRP | R40: =SUM(P40:P45) -> 621741.96
...

Sheet Summary
F1: Date:
F2: By:
A3: BASE YEAR PLANT ECONOMIC SUMMARY
A4: Location: Awaso-Anhwiaso, Ghana | E4: Product (s): Poly-Aluminum Chloride (PAC)
A5: Capital Investment | E5: Plant Life: 20 years
A6: Total Capital Investment | C6: =CashFlow!B10 -> 19946733 | E6: CE Index (2001) | F6: 394.3
A7: Working Capital | C7: =CashFlow!B6 -> 2010354 | E7: CE Index (2026) | F7: 673.8
A8: Salvage Value | C8: =CashFlow!B11 -> 1244957.3 | E8: CEPCI Ratio | F8: =F7/F6 -> 1.7088511
A9: Domestic Volume (TPA) | C9: =CashFlow!B19 -> 4000 | E9: Days | F9: 330
A10: Discounted Cash Flow Rate of Return (DCFRR/IRR) | C10: =CashFlow!B73 -> 0.14816014 | E10: Annual production | F10: 31384.63
A11: Discount Rate (WACC) (From African Dev't Bank) | C11: =CashFlow!B15 -> 0.08 | E11: Inflation rate | F11: =CashFlow!B16 -> 0.04
A12: Net Present Value (NPV) | C12: =CashFlow!B71*1000000 -> 14864691 | E12: Price Escalation | F12: =CashFlow!B17 -> 0.04
A13: Cost of Production | C13: =CashFlow!B74 -> 405.26443
A15: Raw Material | C15: Flow (kg/hr) | D15: Annual (t/opera-yr) | E15: Unit Price ($/t) | F15: Annual Cost (USD) | G15: $/tonne of PAC
A16: Awaso Bauxite (ROM ore) | C16: =CashFlow!H7 -> 755.99 | D16: =CashFlow!I7 -> 5987.4408 | E16: =CashFlow!J7 -> 35 | F16: =CashFlow!K7 -> 209560.43 | G16: =F16/$F$10 -> 6.6771674
A17: Hydrochloric Acid 32 wt% | C17: =CashFlow!H8 -> 2285 | D17: =CashFlow!I8 -> 18097.2 | E17: =CashFlow!J8 -> 180 | F17: =CashFlow!K8 -> 3257496 | G17: =F17/$F$10 -> 103.79272
A18: Calcium Aluminate (CaAl₂O₄) | C18: =CashFlow!H9 -> 650 | D18: =CashFlow!I9 -> 5148 | E18: =CashFlow!J9 -> 310 | F18: =CashFlow!K9 -> 1595880 | G18: =F18/$F$10 -> 50.849094
A19: Carbon Monoxide (industrial grade) | C19: =CashFlow!H10 -> 329.25 | D19: =CashFlow!I10 -> 2607.66 | E19: =CashFlow!J10 -> 450 | F19: =CashFlow!K10 -> 1173447 | G19: =F19/$F$10 -> 37.389225
A20: Process Water | C20: =CashFlow!H11 -> 833.33 | D20: =CashFlow!I11 -> 6599.9736 | E20: =CashFlow!J11 -> 2.73 | F20: =CashFlow!K11 -> 18017.928 | G20: =F20/$F$10 -> 0.57410038
A21: Gross | C21: =SUM(C16:C20) -> 4853.57 | D21: =SUM(D16:D20) -> 38440.274 | F21: =SUM(F16:F20) -> 6254401.4 | G21: =SUM(G16:G20) -> 199.2823
A23: By-Product | C23: Raw Material | D23: Annual (t/yr) | E23: Unit Price ($/t) | F23: Annual Rev (USD) | G23: $/tonne of PAC
A24: Domestic Sales | D24: =C9 -> 4000 | E24: =CashFlow!B20 -> 450 | F24: =D24*E24 -> 1800000 | G24: =F24/$F$10 -> 57.352914
A25: Export Sales | D25: =F10-C9 -> 27384.63 | E25: =CashFlow!B21 -> 480 | F25: =D25*E25 -> 13144622 | G25: =F25/$F$10 -> 418.82356
A26: Silica Residue (Pozzolan) | C26: =CashFlow!B25 -> 260.37 | D26: =CashFlow!C25 -> 2062.1304 | E26: =CashFlow!D25 -> 20 | F26: =CashFlow!E25 -> 41242.608 | G26: =F26/$F$10 -> 1.3141021
A27: Magnetite Reject | C27: =CashFlow!B26 -> 57.75 | D27: =CashFlow!C26 -> 457.38 | E27: =CashFlow!D26 -> 50 | F27: =CashFlow!E26 -> 22869 | G27: =F27/$F$10 -> 0.72866878
A28: Total Revenue per tonne of PAC | F28: =SUM(F24:F27) -> 15008734 | G28: =SUM(G24:G27) -> 478.21924
A30: Direct Expenses | C30: Usage Rate | D30: Annual Usage | E30: Unit Rate ($) | F30: Annual Cost (USD) | G30: $/tonne of PAC
A31: Electricity (Load) | C31: =CashFlow!H15 -> 150 | D31: =CashFlow!I15 -> 1188000 | E31: =CashFlow!J15 -> 0.11 | F31: =CashFlow!K15 -> 131179.72 | G31: =F31/$F$10 -> 4.1797441
A32: Cooling Water | C32: =CashFlow!H16 -> 40 | D32: =CashFlow!I16 -> 316800 | E32: =CashFlow!J16 -> 2.7306262 | F32: =CashFlow!K16 -> 865312.22 | G32: =F32/$F$10 -> 27.57121
A33: Logistics & Distribution | F33: =CashFlow!K20 -> 1230000 | G33: =F33/$F$10 -> 39.191158
A34: Other Variable Costs | F34: =CashFlow!K21 -> 180000 | G34: =F34/$F$10 -> 5.7352914
A35: Labor (Shift + Admin) | C35: Headcount model | F35: =CashFlow!K25 -> 822000 | G35: =F35/$F$10 -> 26.191164
A36: Maintenance | C36: 6% of FCI | F36: =CashFlow!K26 -> 804141.61 | G36: =F36/$F$10 -> 25.622147
A37: Insurance | C37: 1.5% of FCI | F37: =CashFlow!K27 -> 201035.4 | G37: =F37/$F$10 -> 6.4055368
A38: Overheads | C38: 20% of (Labor+Maint) | F38: =CashFlow!K28 -> 582731.43 | G38: =F38/$F$10 -> 18.567414
A39: CSR & Environmental | C39: Fixed | F39: =CashFlow!K29 -> 10000 | G39: =F39/$F$10 -> 0.3186273
A40: Property Tax | C40: Fixed | F40: =CashFlow!K30 -> 15000 | G40: =F40/$F$10 -> 0.47794095
A41: Contingency (15%) | F41: =CashFlow!B9 -> 1813339.3 | G41: =F41/F10 -> 57.777942
A42: Total OPEX | F42: =SUM(F31:F41) -> 6654739.7 | G42: =SUM(G31:G41) -> 212.03818
